<robot name="DHAL" xmlns:xacro="http://www.ros.org/wiki/xacro">
    <material name="black">
        <color rgba="0.0 0.0 0.0 1.0"/>
    </material>
    <material name="blue">
        <color rgba="0.0 0.0 0.8 1.0"/>
    </material>
    <material name="green">
        <color rgba="0.0 0.8 0.0 1.0"/>
    </material>
    <material name="grey">
        <color rgba="0.2 0.2 0.2 1.0"/>
    </material>
    <material name="silver">
        <color rgba="0.913725490196 0.913725490196 0.847058823529 1.0"/>
    </material>
    <material name="orange">
        <color rgba="1.0 0.423529411765 0.0392156862745 1.0"/>
    </material>
    <material name="brown">
        <color rgba="0.870588235294 0.811764705882 0.764705882353 1.0"/>
    </material>
    <material name="red">
        <color rgba="0.8 0.0 0.0 1.0"/>
    </material>
    <material name="white">
        <color rgba="1.0 1.0 1.0 1.0"/>
    </material>

    <link name="Pelvis">
        <visual>
            <origin rpy="0 0 0" xyz="0 0 0"/>
            <geometry>
                <mesh filename="URDF_Pelvis.dae" scale="1 1 1"/>
            </geometry>
            <material name="grey"/>
        </visual>
        <collision>
            <origin rpy="0 0.785398 0" xyz="0.03 0 0.03"/>
            <geometry>
                <box size="0.11 0.32 0.09"/>
            </geometry>
        </collision>
        <inertial>
            <origin rpy="0 0 0" xyz="0.031355 0 0.033229"/>
            <mass value="4.509446"/>
            <inertia ixx="0.048788" ixy="0.000009" ixz="0.004549" iyy="0.017194" iyz="-0.000008" izz="0.047451"/>
        </inertial>
    </link>

    <joint name="L_hip_yaw_joint" type="revolute">
        <origin rpy="0 0.785398 0" xyz="0.0 0.1 0.0"/>
        <parent link="Pelvis"/>
        <child link="L_Hip"/>
        <axis xyz="0 0 1"/>
        <dynamics rotor_inertia="0.0724" damping="0" friction="0"/>
        <limit effort="360.0" velocity="10.0" lower="-1.570796" upper="1.570796"/>
    </joint>
    <link name="L_Hip">
        <visual>
            <origin rpy="0 0 0" xyz="0 0 0"/>
            <geometry>
                <mesh filename="URDF_Hip.dae" scale="1 1 1"/>
            </geometry>
            <material name="grey"/>
        </visual>
        <collision>
            <origin rpy="0 1.570796 0" xyz="0 0 -0.07"/>
            <geometry>
                <cylinder radius="0.06" length="0.08"/>
            </geometry>
        </collision>
        <inertial>
            <origin rpy="0 0 0" xyz="0.005763 0.000041 -0.057716"/>
            <mass value="2.157752"/>
            <inertia ixx="0.012282" ixy="0.000006" ixz="-0.000712" iyy="0.011468" iyz="-0.000006" izz="0.003050"/>
        </inertial>
    </link>

    <joint name="L_hip_roll_joint" type="revolute">
        <origin rpy="0 0 0" xyz="0.0502 0.0 -0.07"/>
        <parent link="L_Hip"/>
        <child link="L_Hip_to_Thigh"/>
        <axis xyz="1 0 0"/>
        <dynamics rotor_inertia="0.0724" damping="0" friction="0"/>
        <limit effort="360.0" velocity="10.0" lower="-1.570796" upper="1.570796"/>
    </joint>
    <link name="L_Hip_to_Thigh">
        <visual>
            <origin rpy="0 0 0" xyz="0 0 0"/>
            <geometry>
                <mesh filename="URDF_Hip_to_Thigh_Left.dae" scale="1 1 1"/>
            </geometry>
            <material name="grey"/>
        </visual>
        <collision>
            <origin rpy="1.570796 0 0" xyz="0.096 0.05 0"/>
            <geometry>
                <cylinder radius="0.09" length="0.19"/>
            </geometry>
        </collision>
        <inertial>
            <origin rpy="0 0 0" xyz="0.036558 -0.022079 0.000000"/>
            <mass value="0.794453"/>
            <inertia ixx="0.001546" ixy="-0.001300" ixz="-0.000003" iyy="0.003675" iyz="-0.000001" izz="0.004089"/>
        </inertial>
    </link>

    <joint name="L_hip_pitch_joint" type="revolute">
        <origin rpy="0 -0.785398 0" xyz="0.096 -0.0451 0"/>
        <parent link="L_Hip_to_Thigh"/>
        <child link="L_Thigh"/>
        <axis xyz="0 1 0"/>
        <dynamics rotor_inertia="0.3608" damping="0" friction="0"/>
        <limit effort="600.0" velocity="10.0" lower="-1.570796" upper="1.570796"/>
    </joint>
    <link name="L_Thigh">
        <visual>
            <origin rpy="0 0 0" xyz="0 0 0"/>
            <geometry>
                <mesh filename="URDF_Thigh_Left.dae" scale="1 1 1"/>
            </geometry>
            <material name="grey"/>
        </visual>
        <inertial>
            <origin rpy="0 0 0" xyz="0.000997 0.092833 -0.049785"/>
            <mass value="7.063633"/>
            <inertia ixx="0.187943" ixy="0.000975" ixz="-0.000944" iyy="0.118972" iyz="-0.052278" izz="0.091682"/>
        </inertial>
    </link>

    <joint name="L_knee_joint" type="revolute">
        <origin rpy="0 0 0" xyz="0 0.1507 -0.4"/>
        <parent link="L_Thigh"/>
        <child link="L_Calf"/>
        <axis xyz="0 1 0"/>
        <dynamics rotor_inertia="0.3608" damping="0" friction="0"/>
        <limit effort="600.0" velocity="10.0" lower="0.0872665" upper="2.35619"/>
    </joint>
    <link name="L_Calf">
        <visual>
            <origin rpy="0 0 0" xyz="0 0 0"/>
            <geometry>
                <mesh filename="URDF_Calf_Left.dae" scale="1 1 1"/>
            </geometry>
            <material name="grey"/>
        </visual>
        <collision>
            <origin rpy="0 0 0" xyz="0 0 -0.205"/>
            <geometry>
                <box size="0.1 0.05 0.30"/>
            </geometry>
        </collision>
        <inertial>
            <origin rpy="0 0 0" xyz="-0.006344 -0.000266 -0.163284"/>
            <mass value="4.005008"/>
            <inertia ixx="0.155373" ixy="-0.000032" ixz="0.007138" iyy="0.158280" iyz="-0.001348" izz="0.006546"/>
        </inertial>
    </link>

    <joint name="L_ankle_pitch_joint" type="revolute">
        <origin rpy="0 0 0" xyz="0 0 -0.41"/>
        <parent link="L_Calf"/>
        <child link="L_Universal"/>
        <axis xyz="0 1 0"/>
        <dynamics rotor_inertia="0.0724" damping="0" friction="0"/>
        <limit effort="360.0" velocity="10.0" lower="-0.872665" upper="0.698132"/>
    </joint>
    <link name="L_Universal">
        <visual>
            <origin rpy="0 0 0" xyz="0 0 0"/>
            <geometry>
                <mesh filename="URDF_Universal.dae" scale="1 1 1"/>
            </geometry>
            <material name="grey"/>
        </visual>
        <inertial>
            <origin rpy="0 0 0" xyz="0.000000 0.000000 0.000000"/>
            <mass value="0.209567"/>
            <inertia ixx="0.000048" ixy="0.000000" ixz="0.000000" iyy="0.000089" iyz="0.000000" izz="0.000124"/>
        </inertial>
    </link>

    <joint name="L_ankle_roll_joint" type="revolute">
        <origin rpy="0 0 0" xyz="0 0 0"/>
        <parent link="L_Universal"/>
        <child link="L_Foot"/>
        <axis xyz="1 0 0"/>
        <dynamics rotor_inertia="0.0724" damping="0" friction="0"/>
        <limit effort="360.0" velocity="10.0" lower="-0.523599" upper="0.523599"/>
    </joint>
    <link name="L_Foot">
        <visual>
            <origin rpy="0 0 0" xyz="0 0 0"/>
            <geometry>
                <mesh filename="URDF_Foot.dae" scale="1 1 1"/>
            </geometry>
            <material name="grey"/>
        </visual>
            <collision>
                <origin rpy="0 0 0" xyz="0.065 0 -0.07"/>
                <geometry>
                    <box size="0.18 0.08 0.02"/>
                </geometry>
            </collision>
            <collision>
                <origin rpy="0 0 0" xyz="0.155 0 -0.07"/>
                <geometry>
                    <cylinder length="0.02" radius="0.04"/>
                </geometry>
            </collision>
            <collision>
                <origin rpy="0 0 0" xyz="-0.025 0 -0.07"/>
                <geometry>
                    <cylinder length="0.02" radius="0.04"/>
                </geometry>
            </collision>
        <inertial>
            <origin rpy="0 0 0" xyz="0.004829 -0.000020 -0.035655"/>
            <mass value="0.571816"/>
            <inertia ixx="0.001485" ixy="0.000001" ixz="-0.000942" iyy="0.003882" iyz="0.000000" izz="0.002841"/>
        </inertial>
    </link>

    <joint name="R_hip_yaw_joint" type="revolute">
        <origin rpy="0 0.785398 0" xyz="0.0 -0.1 0"/>
        <parent link="Pelvis"/>
        <child link="R_Hip"/>
        <axis xyz="0 0 1"/>
        <dynamics rotor_inertia="0.0724" damping="0" friction="0"/>
        <limit effort="360.0" velocity="10.0" lower="-1.570796" upper="1.570796"/>
    </joint>
    <link name="R_Hip">
        <visual>
            <origin rpy="0 0 0" xyz="0 0 0"/>
            <geometry>
                <mesh filename="URDF_Hip.dae" scale="1 1 1"/>
            </geometry>
            <material name="grey"/>
        </visual>
        <collision>
            <origin rpy="0 1.570796 0" xyz="0 0 -0.07"/>
            <geometry>
                <cylinder radius="0.06" length="0.08"/>
            </geometry>
        </collision>
        <inertial>
            <origin rpy="0 0 0" xyz="0.005763 0.000041 -0.057716"/>
            <mass value="2.157752"/>
            <inertia ixx="0.012282" ixy="0.000006" ixz="-0.000712" iyy="0.011468" iyz="-0.000006" izz="0.003050"/>
        </inertial>
    </link>

    <joint name="R_hip_roll_joint" type="revolute">
        <origin rpy="0 0 0" xyz="0.0502 0.0 -0.07"/>
        <parent link="R_Hip"/>
        <child link="R_Hip_to_Thigh"/>
        <axis xyz="1 0 0"/>
        <dynamics rotor_inertia="0.0724" damping="0" friction="0"/>
        <limit effort="360.0" velocity="10.0" lower="-1.570796" upper="1.570796"/>
    </joint>
    <link name="R_Hip_to_Thigh">
        <visual>
            <origin rpy="0 0 0" xyz="0 0 0"/>
            <geometry>
                <mesh filename="URDF_Hip_to_Thigh_Right.dae" scale="1 1 1"/>
            </geometry>
            <material name="grey"/>
        </visual>
        <collision>
            <origin rpy="1.570796 0 0" xyz="0.096 -0.05 0"/>
            <geometry>
                <cylinder radius="0.09" length="0.19"/>
            </geometry>
        </collision>
        <inertial>
            <origin rpy="0 0 0" xyz="0.036558 0.022079 0.000000"/>
            <mass value="0.794453"/>
            <inertia ixx="0.001546" ixy="0.001300" ixz="-0.000003" iyy="0.003675" iyz="0.000001" izz="0.004089"/>
        </inertial>
    </link>

    <joint name="R_hip_pitch_joint" type="revolute">
        <origin rpy="0 -0.785398 0" xyz="0.096 0.0451 0"/>
        <parent link="R_Hip_to_Thigh"/>
        <child link="R_Thigh"/>
        <axis xyz="0 1 0"/>
        <dynamics rotor_inertia="0.3608" damping="0" friction="0"/>
        <limit effort="600.0" velocity="10.0" lower="-1.570796" upper="1.570796"/>
    </joint>
    <link name="R_Thigh">
        <visual>
            <origin rpy="0 0 0" xyz="0 0 0"/>
            <geometry>
                <mesh filename="URDF_Thigh_Right.dae" scale="1 1 1"/>
            </geometry>
            <material name="grey"/>
        </visual>
        <inertial>
            <origin rpy="0 0 0" xyz="0.000997 -0.092833 -0.049785"/>
            <mass value="7.063633"/>
            <inertia ixx="0.187943" ixy="-0.000975" ixz="-0.000944" iyy="0.118972" iyz="0.052278" izz="0.091682"/>
        </inertial>
    </link>

    <joint name="R_knee_joint" type="revolute">
        <origin rpy="0 0 0" xyz="0 -0.1507 -0.4"/>
        <parent link="R_Thigh"/>
        <child link="R_Calf"/>
        <axis xyz="0 1 0"/>
        <dynamics rotor_inertia="0.3608" damping="0" friction="0"/>
        <limit effort="600.0" velocity="10.0" lower="0.0872665" upper="2.35619"/>
    </joint>
    <link name="R_Calf">
        <visual>
            <origin rpy="0 0 0" xyz="0 0 0"/>
            <geometry>
                <mesh filename="URDF_Calf_Right.dae" scale="1 1 1"/>
            </geometry>
            <material name="grey"/>
        </visual>
        <collision>
            <origin rpy="0 0 0" xyz="0 0 -0.205"/>
            <geometry>
                <box size="0.1 0.05 0.30"/>
            </geometry>
        </collision>
        <inertial>
            <origin rpy="0 0 0" xyz="-0.006344 0.000266 -0.163284"/>
            <mass value="4.005008"/>
            <inertia ixx="0.155373" ixy="0.000032" ixz="0.007138" iyy="0.158280" iyz="0.001348" izz="0.006546"/>
        </inertial>
    </link>

    <joint name="R_ankle_pitch_joint" type="revolute">
        <origin rpy="0 0 0" xyz="0 0 -0.41"/>
        <parent link="R_Calf"/>
        <child link="R_Universal"/>
        <axis xyz="0 1 0"/>
        <dynamics rotor_inertia="0.0724" damping="0" friction="0"/>
        <limit effort="360.0" velocity="10.0" lower="-0.872665" upper="0.698132"/>
    </joint>
    <link name="R_Universal">
        <visual>
            <origin rpy="0 0 0" xyz="0 0 0"/>
            <geometry>
                <mesh filename="URDF_Universal.dae" scale="1 1 1"/>
            </geometry>
            <material name="grey"/>
        </visual>
        <inertial>
            <origin rpy="0 0 0" xyz="0.000000 0.000000 0.000000"/>
            <mass value="0.209567"/>
            <inertia ixx="0.000048" ixy="0.000000" ixz="0.000000" iyy="0.000089" iyz="0.000000" izz="0.000124"/>
        </inertial>
    </link>

    <joint name="R_ankle_roll_joint" type="revolute">
        <origin rpy="0 0 0" xyz="0 0 0"/>
        <parent link="R_Universal"/>
        <child link="R_Foot"/>
        <axis xyz="1 0 0"/>
        <dynamics rotor_inertia="0.0724" damping="0" friction="0"/>
        <limit effort="360.0" velocity="10.0" lower="-0.523599" upper="0.523599"/>
    </joint>
    <link name="R_Foot">
        <visual>
            <origin rpy="0 0 0" xyz="0 0 0"/>
            <geometry>
                <mesh filename="URDF_Foot.dae" scale="1 1 1"/>
            </geometry>
            <material name="grey"/>
        </visual>
            <collision>
                <origin rpy="0 0 0" xyz="0.065 0 -0.07"/>
                <geometry>
                    <box size="0.18 0.08 0.02"/>
                </geometry>
            </collision>
            <collision>
                <origin rpy="0 0 0" xyz="0.155 0 -0.07"/>
                <geometry>
                    <cylinder length="0.02" radius="0.04"/>
                </geometry>
            </collision>
            <collision>
                <origin rpy="0 0 0" xyz="-0.025 0 -0.07"/>
                <geometry>
                    <cylinder length="0.02" radius="0.04"/>
                </geometry>
            </collision>
        <inertial>
            <origin rpy="0 0 0" xyz="0.004829 -0.000020 -0.035655"/>
            <mass value="0.571816"/>
            <inertia ixx="0.001485" ixy="0.000001" ixz="-0.000942" iyy="0.003882" iyz="0.000000" izz="0.002841"/>
        </inertial>
    </link>

    <joint name="waist_yaw_joint" type="revolute">
        <origin rpy="0 0 0" xyz="0.065 0.0 0.096"/>
        <parent link="Pelvis"/>
        <child link="Torso"/>
        <axis xyz="0 0 1"/>
        <dynamics rotor_inertia="0.0724" damping="0" friction="0"/>
        <limit effort="360.0" velocity="10.0" lower="-1.570796" upper="1.570796"/>
    </joint>
    <link name="Torso">
        <visual>
            <origin rpy="0 0 0" xyz="0 0 0.0"/>
            <geometry>
                <mesh filename="URDF_Torso.dae" scale="1 1 1"/>
            </geometry>
            <material name="grey"/>
        </visual>
        <collision>
            <origin rpy="0 0 0" xyz="0 0 0.2582"/>
            <geometry>
                <box size="0.14 0.242 0.374"/>
            </geometry>
        </collision>
        <inertial>
            <origin rpy="0 0 0" xyz="-0.000571 -0.275 0.192648"/>
            <mass value="10.742786"/>
            <inertia ixx="0.587282" ixy="0.000133" ixz="0.001513" iyy="0.558291" iyz="-0.000890" izz="0.069820"/>
        </inertial>
    </link>

</robot>
