<robot name="DHAL" xmlns:xacro="http://www.ros.org/wiki/xacro">
    <material name="black">
        <color rgba="0.0 0.0 0.0 1.0"/>
    </material>
    <material name="blue">
        <color rgba="0.0 0.0 0.8 1.0"/>
    </material>
    <material name="green">
        <color rgba="0.0 0.8 0.0 1.0"/>
    </material>
    <material name="grey">
        <color rgba="0.2 0.2 0.2 1.0"/>
    </material>
    <material name="silver">
        <color rgba="0.913725490196 0.913725490196 0.847058823529 1.0"/>
    </material>
    <material name="orange">
        <color rgba="1.0 0.423529411765 0.0392156862745 1.0"/>
    </material>
    <material name="brown">
        <color rgba="0.870588235294 0.811764705882 0.764705882353 1.0"/>
    </material>
    <material name="red">
        <color rgba="0.8 0.0 0.0 1.0"/>
    </material>
    <material name="white">
        <color rgba="1.0 1.0 1.0 1.0"/>
    </material>

    <link name="Pelvis">
        <visual>
            <origin rpy="0 0 0" xyz="0 0 0"/>
            <geometry>
                <mesh filename="Pelvis.dae" scale="1 1 1"/>
            </geometry>
            <material name="grey"/>
        </visual>
        <collision>
            <origin rpy="0 0 0" xyz="0 0 0"/>
            <geometry>
                <box size="0.12 0.32 0.1"/>
            </geometry>
        </collision>
        <inertial>
            <origin rpy="0 0 0" xyz="0.001269 0 -0.010588"/>
            <mass value="4.67"/>
            <inertia ixx="0.046054" ixy="0.000012" ixz="0.000301" iyy="0.006762" iyz="0.0" izz="0.04786"/>
        </inertial>
    </link>

    <joint name="L_hip_yaw_joint" type="revolute">
        <origin rpy="0 0 0" xyz="0.0 0.1 -0.0492"/>
        <parent link="Pelvis"/>
        <child link="L_Hip"/>
        <axis xyz="0 0 1"/>
        <dynamics rotor_inertia="0.0724" damping="0" friction="0"/>
        <limit effort="360.0" lower="-0.785398" upper="1.57079632679" velocity="10.0"/>
    </joint>
    <link name="L_Hip">
        <visual>
            <origin rpy="0 0 0" xyz="0 0 0"/>
            <geometry>
                <mesh filename="Hip.dae" scale="1 1 1"/>
            </geometry>
            <material name="grey"/>
        </visual>
        <collision>
            <origin rpy="0 1.57079632679 0" xyz="0 0 -0.07"/>
            <geometry>
                <cylinder radius="0.06" length="0.08"/>
            </geometry>
        </collision>
        <inertial>
            <origin rpy="0 0 0" xyz="0.010407 0.00004 -0.066062"/>
            <mass value="2.204506"/>
            <inertia ixx="0.013818" ixy="0.000008" ixz="-0.001448" iyy="0.013243" iyz="-0.000007" izz="0.03344"/>
        </inertial>
    </link>

    <joint name="L_hip_roll_joint" type="revolute">
        <origin rpy="0 0 0" xyz="0.0502 0.0 -0.07"/>
        <parent link="L_Hip"/>
        <child link="L_Hip_Pitch"/>
        <axis xyz="1 0 0"/>
        <dynamics rotor_inertia="0.0724" damping="0" friction="0"/>
        <limit effort="360.0" lower="-0.349066" upper="0.785398" velocity="10.0"/>
    </joint>
    <link name="L_Hip_Pitch">
        <visual>
            <origin rpy="0 0 0" xyz="0 0 0"/>
            <geometry>
                <mesh filename="Hip_Pitch.dae" scale="1 1 1"/>
            </geometry>
            <material name="grey"/>
        </visual>
        <collision>
            <origin rpy="1.57079632679 0 0" xyz="0.096 0.005 0"/>
            <geometry>
                <cylinder radius="0.09" length="0.1"/>
            </geometry>
        </collision>
        <inertial>
            <origin rpy="0 0 0" xyz="0.038459 -0.034907 0"/>
            <mass value="0.260453"/>
            <inertia ixx="0.000662" ixy="-0.000480" ixz="-0.000001" iyy="0.000964" iyz="-0.000001" izz="0.001216"/>
        </inertial>
    </link>

    <joint name="L_hip_pitch_joint" type="revolute">
        <origin rpy="0 0 0" xyz="0.096 -0.0451 0"/>
        <parent link="L_Hip_Pitch"/>
        <child link="L_Thigh"/>
        <axis xyz="0 1 0"/>
        <dynamics rotor_inertia="0.3608" damping="0" friction="0"/>
        <limit effort="600.0" lower="-1.57079632679" upper="1.57079632679" velocity="10.0"/>
    </joint>
    <link name="L_Thigh">
        <visual>
            <origin rpy="0 0 0" xyz="0 0 0"/>
            <geometry>
                <mesh filename="Thigh.dae" scale="1 1 1"/>
            </geometry>
            <material name="grey"/>
        </visual>
        <!-- <collision>
            <origin rpy="0 0 0" xyz="0 0.1507 -0.2"/>
            <geometry>
                <box size="0.12 0.06 0.26"/>
            </geometry>
        </collision> -->
        <inertial>
            <origin rpy="0 0 0" xyz="0.000969 0.090508 -0.048393"/>
            <mass value="7.267508"/>
            <inertia ixx="0.111572" ixy="0.000337" ixz="-0.000604" iyy="0.102236" iyz="-0.020450" izz="0.032320"/>
        </inertial>
    </link>

    <joint name="L_knee_joint" type="revolute">
        <origin rpy="0 0 0" xyz="0 0.1507 -0.4"/>
        <parent link="L_Thigh"/>
        <child link="L_Calf"/>
        <axis xyz="0 1 0"/>
        <dynamics rotor_inertia="0.3608" damping="0" friction="0"/>
        <limit effort="600.0" lower="0.0872665" upper="2.35619" velocity="10.0"/>
    </joint>
    <link name="L_Calf">
        <visual>
            <origin rpy="0 0 0" xyz="0 0 0"/>
            <geometry>
                <mesh filename="Calf.dae" scale="1 1 1"/>
            </geometry>
            <material name="grey"/>
        </visual>
        <collision>
            <origin rpy="0 0 0" xyz="0 0 -0.205"/>
            <geometry>
                <box size="0.1 0.05 0.30"/>
            </geometry>
        </collision>
        <inertial>
            <origin rpy="0 0 0" xyz="-0.005889 -0.000266 -0.161600"/>
            <mass value="4.005008"/>
            <inertia ixx="0.151252" ixy="-0.000025" ixz="0.006597" iyy="0.154221" iyz="-0.001379" izz="0.006609"/>
        </inertial>
    </link>

    <joint name="L_ankle_pitch_joint" type="revolute">
        <origin rpy="0 0 0" xyz="0 0 -0.41"/>
        <parent link="L_Calf"/>
        <child link="L_Ankle"/>
        <axis xyz="0 1 0"/>
        <dynamics rotor_inertia="0.023168" damping="0" friction="0"/>
        <limit effort="150.0" lower="-1.22173" upper="0.349066" velocity="10.0"/>
    </joint>
    <link name="L_Ankle">
        <!-- <visual>
            <origin rpy="1.57079632679 0 0" xyz="0 0 0"/>
            <geometry>
                <cylinder length="0.05" radius="0.02"/>
            </geometry>
            <material name="white"/>
        </visual>
        <collision>
            <origin rpy="1.57079632679 0 0" xyz="0 0 0"/>
            <geometry>
                <cylinder length="0.06" radius="0.02"/>
            </geometry>
        </collision> -->
        <inertial>
            <origin rpy="0 0 0" xyz="0 0 0"/>
            <mass value="0.01"/>
            <inertia ixx="1E-06" ixy="0.0" ixz="0.0" iyy="1E-06" iyz="0.0" izz="1E-06"/>
        </inertial>
    </link>

    <joint name="L_ankle_roll_joint" type="revolute">
        <origin rpy="0 0 0" xyz="0 0 0"/>
        <parent link="L_Ankle"/>
        <child link="L_Foot"/>
        <axis xyz="1 0 0"/>
        <dynamics rotor_inertia="0.023168" damping="0" friction="0"/>
        <limit effort="150.0" lower="-0.523599" upper="0.523599" velocity="10.0"/>
    </joint>
    <link name="L_Foot">
        <visual>
            <origin rpy="0 0 0" xyz="0 0 0"/>
            <geometry>
                <mesh filename="Foot.dae" scale="1 1 1"/>
            </geometry>
            <material name="blue"/>
        </visual>
        <collision>
            <origin rpy="0 0 0" xyz="0.06 0 -0.07"/>
            <geometry>
                <box size="0.26 0.08 0.02"/>
            </geometry>
        </collision>
        <inertial>
            <origin rpy="0 0 0" xyz="0.03534 -0.000014 -0.026092"/>
            <mass value="0.781383"/>
            <inertia ixx="0.001532" ixy="0.000001" ixz="-0.000942" iyy="0.003971" iyz="0.000000" izz="0.002965"/>
        </inertial>
    </link>

    <!-- =================================================== -->

    <joint name="R_hip_yaw_joint" type="revolute">
        <origin rpy="0 0 0" xyz="0.0 -0.1 -0.0492"/>
        <parent link="Pelvis"/>
        <child link="R_Hip"/>
        <axis xyz="0 0 1"/>
        <dynamics rotor_inertia="0.0724" damping="0" friction="0"/>
        <limit effort="360.0" lower="-1.57079632679" upper="0.785398" velocity="10.0"/>
    </joint>
    <link name="R_Hip">
        <visual>
            <origin rpy="0 0 0" xyz="0 0 0"/>
            <geometry>
                <mesh filename="Hip.dae" scale="1 1 1"/>
            </geometry>
            <material name="grey"/>
        </visual>
        <collision>
            <origin rpy="0 1.57079632679 0" xyz="0 0 -0.07"/>
            <geometry>
                <cylinder radius="0.06" length="0.08"/>
            </geometry>
        </collision>
        <inertial>
            <origin rpy="0 1.57079632679 0" xyz="0.010407 0.00004 -0.066062"/>
            <mass value="2.204506"/>
            <inertia ixx="0.013818" ixy="0.000008" ixz="-0.001448" iyy="0.013243" iyz="-0.000007" izz="0.03344"/>
        </inertial>
    </link>

    <joint name="R_hip_roll_joint" type="revolute">
        <origin rpy="0 0 0" xyz="0.0502 0.0 -0.07"/>
        <parent link="R_Hip"/>
        <child link="R_Hip_Pitch"/>
        <axis xyz="1 0 0"/>
        <dynamics rotor_inertia="0.0724" damping="0" friction="0"/>
        <limit effort="360.0" lower="-0.785398" upper="0.349066" velocity="10.0"/>
    </joint>
    <link name="R_Hip_Pitch">
        <visual>
            <origin rpy="0 0 0" xyz="0 0 0"/>
            <geometry>
                <mesh filename="Hip_Pitch_mir.dae" scale="1 1 1"/>
            </geometry>
            <material name="white"/>
        </visual>
        <collision>
            <origin rpy="1.57079632679 0 0" xyz="0.096 -0.005 0"/>
            <geometry>
                <cylinder radius="0.09" length="0.1"/>
            </geometry>
        </collision>
        <inertial>
            <origin rpy="0 0 0" xyz="0.038459 0.034907 0"/>
            <mass value="0.260453"/>
            <inertia ixx="0.000662" ixy="0.000480" ixz="-0.000001" iyy="0.000964" iyz="0.000001" izz="0.001216"/>
        </inertial>
    </link>

    <joint name="R_hip_pitch_joint" type="revolute">
        <origin rpy="0 0 0" xyz="0.096 0.0451 0"/>
        <parent link="R_Hip_Pitch"/>
        <child link="R_Thigh"/>
        <axis xyz="0 1 0"/>
        <dynamics rotor_inertia="0.3608" damping="0" friction="0"/>
        <limit effort="600.0" lower="-1.57079632679" upper="1.57079632679" velocity="10.0"/>
    </joint>
    <link name="R_Thigh">
        <visual>
            <origin rpy="0 0 0" xyz="0 0.0 0.0"/>
            <geometry>
                <mesh filename="Thigh_mir.dae" scale="1 1 1"/>
            </geometry>
            <material name="grey"/>
        </visual>
        <!-- <collision>
            <origin rpy="0 0 0" xyz="0 -0.1507 -0.2"/>
            <geometry>
                <box size="0.12 0.06 0.26"/>
            </geometry>
        </collision> -->
        <inertial>
            <origin rpy="0 0 0" xyz="0.000969 -0.090508 -0.048393"/>
            <mass value="7.267508"/>
            <inertia ixx="0.111572" ixy="-0.000337" ixz="-0.000604" iyy="0.102236" iyz="0.020450" izz="0.032320"/>
        </inertial>
    </link>

    <joint name="R_knee_joint" type="revolute">
        <origin rpy="0 0 0" xyz="0 -0.1507 -0.4"/>
        <parent link="R_Thigh"/>
        <child link="R_Calf"/>
        <axis xyz="0 1 0"/>
        <dynamics rotor_inertia="0.3608" damping="0" friction="0"/>
        <limit effort="600.0" lower="0.0872665" upper="2.35619" velocity="10.0"/>
    </joint>
    <link name="R_Calf">
        <visual>
            <origin rpy="0 0 0" xyz="0 0 0"/>
            <geometry>
                <mesh filename="Calf_mir.dae" scale="1 1 1"/>
            </geometry>
            <material name="grey"/>
        </visual>
        <collision>
            <origin rpy="0 0 0" xyz="0 0 -0.205"/>
            <geometry>
                <box size="0.1 0.05 0.30"/>
            </geometry>
        </collision>
        <inertial>
            <origin rpy="0 0 0" xyz="-0.005889 0.000266 -0.161600"/>
            <mass value="4.005008"/>
            <inertia ixx="0.151252" ixy="0.000025" ixz="0.006597" iyy="0.154221" iyz="0.001379" izz="0.006609"/>
        </inertial>
    </link>

    <joint name="R_ankle_pitch_joint" type="revolute">
        <origin rpy="0 0 0" xyz="0 0 -0.41"/>
        <parent link="R_Calf"/>
        <child link="R_Ankle"/>
        <axis xyz="0 1 0"/>
        <dynamics rotor_inertia="0.023168" damping="0" friction="0"/>
        <limit effort="150.0" lower="-1.22173" upper="0.349066" velocity="10.0"/>
    </joint>
    <link name="R_Ankle">
        <!-- <visual>
            <origin rpy="1.57079632679 0 0" xyz="0 0 0"/>
            <geometry>
                <cylinder length="0.05" radius="0.02"/>
            </geometry>
            <material name="white"/>
        </visual>
        <collision>
            <origin rpy="1.57079632679 0 0" xyz="0 0 0"/>
            <geometry>
                <cylinder length="0.06" radius="0.02"/>
            </geometry>
        </collision> -->
        <inertial>
            <origin rpy="0 0 0" xyz="0 0 0"/>
            <mass value="0.01"/>
            <inertia ixx="1E-06" ixy="0.0" ixz="0.0" iyy="1E-06" iyz="0.0" izz="1E-06"/>
        </inertial>
    </link>

    <joint name="R_ankle_roll_joint" type="revolute">
        <origin rpy="0 0 0" xyz="0 0 0"/>
        <parent link="R_Ankle"/>
        <child link="R_Foot"/>
        <axis xyz="1 0 0"/>
        <dynamics rotor_inertia="0.023168" damping="0" friction="0"/>
        <limit effort="150.0" lower="-0.523599" upper="0.523599" velocity="10.0"/>
    </joint>
    <link name="R_Foot">
        <visual>
            <origin rpy="0 0 0" xyz="0 0 0.0"/>
            <geometry>
                <mesh filename="Foot.dae" scale="1 1 1"/>
            </geometry>
            <material name="red"/>
        </visual>
        <collision>
            <origin rpy="0 0 0" xyz="0.06 0 -0.07"/>
            <geometry>
                <box size="0.26 0.08 0.02"/>
            </geometry>
        </collision>
        <inertial>
            <origin rpy="0 0 0" xyz="0.03534 -0.000014 -0.026092"/>
            <mass value="0.781383"/>
            <inertia ixx="0.001532" ixy="0.000001" ixz="-0.000942" iyy="0.003971" iyz="0.000000" izz="0.002965"/>
        </inertial>
    </link>

    <joint name="waist_yaw_joint" type="revolute">
        <origin rpy="0 0 0" xyz="0.04 0 0.052"/>
        <parent link="Pelvis"/>
        <child link="Torso"/>
        <axis xyz="0 0 1"/>
        <dynamics rotor_inertia="0.0724" damping="0" friction="0"/>
        <limit effort="360.0" lower="-0.785398" upper="0.785398" velocity="10.0"/>
    </joint>
    <link name="Torso">
        <visual>
            <origin rpy="0 0 0" xyz="0 0 0"/>
            <geometry>
                <mesh filename="Torso.dae" scale="1 1 1"/>
            </geometry>
            <material name="grey"/>
        </visual>
        <!-- <collision>
            <origin rpy="0 0 0" xyz="0 0 0.22"/>
            <geometry>
                <box size="0.14 0.3 0.4"/>
            </geometry>
        </collision> -->
        <inertial>
            <origin rpy="0 0 0" xyz="0 0 0.22"/>
            <mass value="12"/>
            <inertia ixx="1.0" ixy="0.0" ixz="0.0" iyy="1.0" iyz="0.0" izz="1.0"/>
        </inertial>
    </link>

 </robot>
